În testarea software, "testarea excepțiilor" (testing exceptions) și utilizarea lui `assertThrows` sunt două concepte importante care ajută la asigurarea calității codului și la gestionarea corespunzătoare a erorilor. 

### Testarea Excepțiilor

Testarea excepțiilor implică verificarea faptului că o anumită parte a codului aruncă excepțiile așteptate atunci când întâmpină condiții anormale sau de eroare. Acest tip de testare este esențial pentru a confirma că aplicația gestionează corect scenariile neașteptate și că excepțiile sunt tratate corespunzător.

#### Exemple comune de testare a excepțiilor:

1. **Validarea intrărilor utilizatorului**: Verificarea dacă aplicația aruncă o excepție atunci când utilizatorul introduce date invalide.
2. **Gestionarea erorilor de rețea**: Confirmarea că aplicația aruncă o excepție atunci când nu poate comunica cu un server.
3. **Erori de bază de date**: Verificarea dacă aplicația gestionează corect erorile care apar atunci când baza de date nu este disponibilă sau când există probleme cu interogările SQL.

### Utilizarea lui `assertThrows`

`assertThrows` este o metodă folosită în testarea unităților pentru a verifica dacă o anumită secvență de cod aruncă o excepție specificată. Este disponibilă în multe framework-uri de testare, cum ar fi JUnit pentru Java.

#### Sintaxa în JUnit (Java):

```java
@Test
void testMethodShouldThrowException() {
    Exception exception = assertThrows(ExpectedException.class, () -> {
        // codul care ar trebui să arunce excepția
    });
    
    // opțional, puteți verifica mesajul excepției
    assertEquals("Expected message", exception.getMessage());
}
```

### Exemplu practic

Să presupunem că avem o metodă care împarte două numere și aruncă o excepție atunci când împărțitorul este zero. Iată cum am putea testa acest lucru utilizând `assertThrows` în JUnit:

#### Codul metodei:

```java
public class Calculator {
    public double divide(double numerator, double denominator) {
        if (denominator == 0) {
            throw new IllegalArgumentException("Denominator cannot be zero");
        }
        return numerator / denominator;
    }
}
```

#### Codul testului:

```java
import static org.junit.jupiter.api.Assertions.assertThrows;

import org.junit.jupiter.api.Test;

class CalculatorTest {

    @Test
    void divideShouldThrowExceptionWhenDenominatorIsZero() {
        Calculator calculator = new Calculator();
        
        Exception exception = assertThrows(IllegalArgumentException.class, () -> {
            calculator.divide(10, 0);
        });
        
        assertEquals("Denominator cannot be zero", exception.getMessage());
    }
}
```

### Concluzie

Testarea excepțiilor și utilizarea lui `assertThrows` sunt instrumente valoroase în asigurarea că aplicațiile software tratează corect situațiile de eroare. Aceste practici contribuie la creșterea robustetei și fiabilității codului, asigurându-se că erorile sunt gestionate într-un mod previzibil și controlat.
